Workbook

Sheet Raw_Data
A1: OrderID | B1: Date | C1: CustomerID | D1: Product | E1: Quantity | F1: UnitPrice | G1: ShippingAddress | H1: PaymentMethod | I1: OrderStatus | J1: TrackingNumber | K1: ItemsInCart | L1: CouponCode | M1: ReferralSource | N1: TotalPrice | O1: Duplicate_Check | P1: Missing_Check | Q1: Date_Check | R1: Precision_Check
A2: ORD200000 | B2: 44930 | C2: C72649 | D2: Monitor | E2: 5 | F2: 570.62 | G2: 928 Main St | H2: Debit Card | I2: Shipped | J2: TRK37947903 | K2: 7 | L2: SAVE10 | M2: Instagram | N2: 2853.1 | O2: =IF(COUNTIF($A$2:$A$1201,A2)>1,"DUPLICATE","Unique") -> Unique | P2: =IF(L2="","MISSING","OK") -> OK | Q2: =IF(ISNUMBER(B2),"OK","BAD DATE") -> OK | R2: =IF(ROUND(F2,2)=F2,"OK","FIX") -> OK
A3: ORD200001 | B3: 45527 | C3: C75739 | D3: Phone | E3: 2 | F3: 151.35 | G3: 823 Main St | H3: Online | I3: Shipped | J3: TRK91186779 | K3: 3 | L3: SAVE10 | M3: Referral | N3: 302.7 | O3: =IF(COUNTIF($A$2:$A$1201,A3)>1,"DUPLICATE","Unique") -> Unique | P3: =IF(L3="","MISSING","OK") -> OK | Q3: =IF(ISNUMBER(B3),"OK","BAD DATE") -> OK | R3: =IF(ROUND(F3,2)=F3,"OK","FIX") -> OK
A4: ORD200002 | B4: 45349 | C4: C81728 | D4: Tablet | E4: 5 | F4: 550.68 | G4: 512 Main St | H4: Credit Card | I4: Cancelled | J4: TRK42903982 | K4: 8 | L4: FREESHIP | M4: Email | N4: 2753.4 | O4: =IF(COUNTIF($A$2:$A$1201,A4)>1,"DUPLICATE","Unique") -> Unique | P4: =IF(L4="","MISSING","OK") -> OK | Q4: =IF(ISNUMBER(B4),"OK","BAD DATE") -> OK | R4: =IF(ROUND(F4,2)=F4,"OK","FIX") -> OK
A5: ORD200003 | B5: 45214 | C5: C33540 | D5: Chair | E5: 1 | F5: 273.19 | G5: 275 Main St | H5: Debit Card | I5: Returned | J5: TRK62788070 | K5: 5 | L5: SAVE10 | M5: Facebook | N5: 273.19 | O5: =IF(COUNTIF($A$2:$A$1201,A5)>1,"DUPLICATE","Unique") -> Unique | P5: =IF(L5="","MISSING","OK") -> OK | Q5: =IF(ISNUMBER(B5),"OK","BAD DATE") -> OK | R5: =IF(ROUND(F5,2)=F5,"OK","FIX") -> OK
A6: ORD200004 | B6: 45785 | C6: C81840 | D6: Printer | E6: 4 | F6: 626.01 | G6: 668 Main St | H6: Online | I6: Delivered | J6: TRK29241424 | K6: 8 | L6: SAVE10 | M6: Email | N6: 2504.04 | O6: =IF(COUNTIF($A$2:$A$1201,A6)>1,"DUPLICATE","Unique") -> Unique | P6: =IF(L6="","MISSING","OK") -> OK | Q6: =IF(ISNUMBER(B6),"OK","BAD DATE") -> OK | R6: =IF(ROUND(F6,2)=F6,"OK","FIX") -> OK
A7: ORD200005 | B7: 45222 | C7: C37249 | D7: Phone | E7: 2 | F7: 245.86 | G7: 934 Main St | H7: Credit Card | I7: Shipped | J7: TRK72976927 | K7: 4 | L7: SAVE10 | M7: Instagram | N7: 491.72 | O7: =IF(COUNTIF($A$2:$A$1201,A7)>1,"DUPLICATE","Unique") -> Unique | P7: =IF(L7="","MISSING","OK") -> OK | Q7: =IF(ISNUMBER(B7),"OK","BAD DATE") -> OK | R7: =IF(ROUND(F7,2)=F7,"OK","FIX") -> OK
A8: ORD200006 | B8: 45825 | C8: C83492 | D8: Laptop | E8: 1 | F8: 664.42 | G8: 986 Main St | H8: Gift Card | I8: Returned | J8: TRK96417362 | K8: 6 | L8: SAVE10 | M8: Facebook | N8: 664.42 | O8: =IF(COUNTIF($A$2:$A$1201,A8)>1,"DUPLICATE","Unique") -> Unique | P8: =IF(L8="","MISSING","OK") -> OK | Q8: =IF(ISNUMBER(B8),"OK","BAD DATE") -> OK | R8: =IF(ROUND(F8,2)=F8,"OK","FIX") -> OK
A9: ORD200007 | B9: 45058 | C9: C41460 | D9: Monitor | E9: 5 | F9: 149.55 | G9: 706 Main St | H9: Cash | I9: Shipped | J9: TRK78809193 | K9: 9 | L9: FREESHIP | M9: Facebook | N9: 747.75 | O9: =IF(COUNTIF($A$2:$A$1201,A9)>1,"DUPLICATE","Unique") -> Unique | P9: =IF(L9="","MISSING","OK") -> OK | Q9: =IF(ISNUMBER(B9),"OK","BAD DATE") -> OK | R9: =IF(ROUND(F9,2)=F9,"OK","FIX") -> OK
A10: ORD200008 | B10: 45749 | C10: C26817 | D10: Phone | E10: 2 | F10: 134.28 | G10: 904 Main St | H10: Gift Card | I10: Cancelled | J10: TRK61042692 | K10: 2 | M10: Email | N10: 268.56 | O10: =IF(COUNTIF($A$2:$A$1201,A10)>1,"DUPLICATE","Unique") -> Unique | P10: =IF(L10="","MISSING","OK") -> MISSING | Q10: =IF(ISNUMBER(B10),"OK","BAD DATE") -> OK | R10: =IF(ROUND(F10,2)=F10,"OK","FIX") -> OK
A11: ORD200009 | B11: 45251 | C11: C31946 | D11: Desk | E11: 4 | F11: 509.38 | G11: 102 Main St | H11: Credit Card | I11: Shipped | J11: TRK33478363 | K11: 6 | L11: SAVE10 | M11: Google | N11: 2037.52 | O11: =IF(COUNTIF($A$2:$A$1201,A11)>1,"DUPLICATE","Unique") -> Unique | P11: =IF(L11="","MISSING","OK") -> OK | Q11: =IF(ISNUMBER(B11),"OK","BAD DATE") -> OK | R11: =IF(ROUND(F11,2)=F11,"OK","FIX") -> OK
A12: ORD200010 | B12: 45289 | C12: C43443 | D12: Tablet | E12: 5 | F12: 625.97 | G12: 333 Main St | H12: Credit Card | I12: Returned | J12: TRK98859248 | K12: 9 | L12: WINTER15 | M12: Instagram | N12: 3129.85 | O12: =IF(COUNTIF($A$2:$A$1201,A12)>1,"DUPLICATE","Unique") -> Unique | P12: =IF(L12="","MISSING","OK") -> OK | Q12: =IF(ISNUMBER(B12),"OK","BAD DATE") -> OK | R12: =IF(ROUND(F12,2)=F12,"OK","FIX") -> OK
A13: ORD200011 | B13: 45339 | C13: C93861 | D13: Monitor | E13: 3 | F13: 49.14 | G13: 831 Main St | H13: Online | I13: Returned | J13: TRK48234646 | K13: 7 | L13: SAVE10 | M13: Email | N13: 147.42 | O13: =IF(COUNTIF($A$2:$A$1201,A13)>1,"DUPLICATE","Unique") -> Unique | P13: =IF(L13="","MISSING","OK") -> OK | Q13: =IF(ISNUMBER(B13),"OK","BAD DATE") -> OK | R13: =IF(ROUND(F13,2)=F13,"OK","FIX") -> OK
A14: ORD200012 | B14: 45580 | C14: C38785 | D14: Monitor | E14: 2 | F14: 180.5 | G14: 179 Main St | H14: Debit Card | I14: Pending | J14: TRK20419991 | K14: 6 | L14: FREESHIP | M14: Referral | N14: 361 | O14: =IF(COUNTIF($A$2:$A$1201,A14)>1,"DUPLICATE","Unique") -> Unique | P14: =IF(L14="","MISSING","OK") -> OK | Q14: =IF(ISNUMBER(B14),"OK","BAD DATE") -> OK | R14: =IF(ROUND(F14,2)=F14,"OK","FIX") -> OK
A15: ORD200013 | B15: 45168 | C15: C88348 | D15: Laptop | E15: 3 | F15: 201.49 | G15: 903 Main St | H15: Credit Card | I15: Returned | J15: TRK81913874 | K15: 4 | L15: FREESHIP | M15: Facebook | N15: 604.47 | O15: =IF(COUNTIF($A$2:$A$1201,A15)>1,"DUPLICATE","Unique") -> Unique | P15: =IF(L15="","MISSING","OK") -> OK | Q15: =IF(ISNUMBER(B15),"OK","BAD DATE") -> OK | R15: =IF(ROUND(F15,2)=F15,"OK","FIX") -> OK
A16: ORD200014 | B16: 45012 | C16: C98474 | D16: Tablet | E16: 2 | F16: 393.33 | G16: 980 Main St | H16: Debit Card | I16: Pending | J16: TRK79186539 | K16: 3 | L16: SAVE10 | M16: Instagram | N16: 786.66 | O16: =IF(COUNTIF($A$2:$A$1201,A16)>1,"DUPLICATE","Unique") -> Unique | P16: =IF(L16="","MISSING","OK") -> OK | Q16: =IF(ISNUMBER(B16),"OK","BAD DATE") -> OK | R16: =IF(ROUND(F16,2)=F16,"OK","FIX") -> OK
A17: ORD200015 | B17: 45124 | C17: C39416 | D17: Printer | E17: 1 | F17: 473.96 | G17: 942 Main St | H17: Cash | I17: Delivered | J17: TRK54930938 | K17: 3 | M17: Google | N17: 473.96 | O17: =IF(COUNTIF($A$2:$A$1201,A17)>1,"DUPLICATE","Unique") -> Unique | P17: =IF(L17="","MISSING","OK") -> MISSING | Q17: =IF(ISNUMBER(B17),"OK","BAD DATE") -> OK | R17: =IF(ROUND(F17,2)=F17,"OK","FIX") -> OK
A18: ORD200016 | B18: 44950 | C18: C28976 | D18: Printer | E18: 2 | F18: 533.81 | G18: 914 Main St | H18: Credit Card | I18: Pending | J18: TRK13194259 | K18: 3 | L18: FREESHIP | M18: Email | N18: 1067.62 | O18: =IF(COUNTIF($A$2:$A$1201,A18)>1,"DUPLICATE","Unique") -> Unique | P18: =IF(L18="","MISSING","OK") -> OK | Q18: =IF(ISNUMBER(B18),"OK","BAD DATE") -> OK | R18: =IF(ROUND(F18,2)=F18,"OK","FIX") -> OK
A19: ORD200017 | B19: 45353 | C19: C60672 | D19: Tablet | E19: 1 | F19: 423.4 | G19: 382 Main St | H19: Debit Card | I19: Shipped | J19: TRK11972116 | K19: 3 | M19: Referral | N19: 423.4 | O19: =IF(COUNTIF($A$2:$A$1201,A19)>1,"DUPLICATE","Unique") -> Unique | P19: =IF(L19="","MISSING","OK") -> MISSING | Q19: =IF(ISNUMBER(B19),"OK","BAD DATE") -> OK | R19: =IF(ROUND(F19,2)=F19,"OK","FIX") -> OK
A20: ORD200018 | B20: 45742 | C20: C84329 | D20: Desk | E20: 1 | F20: 431.44 | G20: 891 Main St | H20: Gift Card | I20: Pending | J20: TRK65191045 | K20: 3 | L20: SAVE10 | M20: Facebook | N20: 431.44 | O20: =IF(COUNTIF($A$2:$A$1201,A20)>1,"DUPLICATE","Unique") -> Unique | P20: =IF(L20="","MISSING","OK") -> OK | Q20: =IF(ISNUMBER(B20),"OK","BAD DATE") -> OK | R20: =IF(ROUND(F20,2)=F20,"OK","FIX") -> OK
A21: ORD200019 | B21: 44949 | C21: C14552 | D21: Monitor | E21: 5 | F21: 224 | G21: 273 Main St | H21: Cash | I21: Returned | J21: TRK59101365 | K21: 9 | L21: SAVE10 | M21: Google | N21: 1120 | O21: =IF(COUNTIF($A$2:$A$1201,A21)>1,"DUPLICATE","Unique") -> Unique | P21: =IF(L21="","MISSING","OK") -> OK | Q21: =IF(ISNUMBER(B21),"OK","BAD DATE") -> OK | R21: =IF(ROUND(F21,2)=F21,"OK","FIX") -> OK
A22: ORD200020 | B22: 45054 | C22: C54829 | D22: Chair | E22: 5 | F22: 62.51 | G22: 587 Main St | H22: Cash | I22: Pending | J22: TRK16718651 | K22: 9 | L22: WINTER15 | M22: Instagram | N22: 312.55 | O22: =IF(COUNTIF($A$2:$A$1201,A22)>1,"DUPLICATE","Unique") -> Unique | P22: =IF(L22="","MISSING","OK") -> OK | Q22: =IF(ISNUMBER(B22),"OK","BAD DATE") -> OK | R22: =IF(ROUND(F22,2)=F22,"OK","FIX") -> OK
A23: ORD200021 | B23: 45613 | C23: C99023 | D23: Monitor | E23: 4 | F23: 342.95 | G23: 569 Main St | H23: Cash | I23: Delivered | J23: TRK52646983 | K23: 6 | M23: Google | N23: 1371.8 | O23: =IF(COUNTIF($A$2:$A$1201,A23)>1,"DUPLICATE","Unique") -> Unique | P23: =IF(L23="","MISSING","OK") -> MISSING | Q23: =IF(ISNUMBER(B23),"OK","BAD DATE") -> OK | R23: =IF(ROUND(F23,2)=F23,"OK","FIX") -> OK
A24: ORD200022 | B24: 44955 | C24: C34416 | D24: Monitor | E24: 2 | F24: 49.62 | G24: 633 Main St | H24: Online | I24: Pending | J24: TRK75937350 | K24: 2 | L24: SAVE10 | M24: Google | N24: 99.24 | O24: =IF(COUNTIF($A$2:$A$1201,A24)>1,"DUPLICATE","Unique") -> Unique | P24: =IF(L24="","MISSING","OK") -> OK | Q24: =IF(ISNUMBER(B24),"OK","BAD DATE") -> OK | R24: =IF(ROUND(F24,2)=F24,"OK","FIX") -> OK
A25: ORD200023 | B25: 45756 | C25: C42372 | D25: Phone | E25: 4 | F25: 273.25 | G25: 755 Main St | H25: Debit Card | I25: Cancelled | J25: TRK36168083 | K25: 5 | L25: FREESHIP | M25: Referral | N25: 1093 | O25: =IF(COUNTIF($A$2:$A$1201,A25)>1,"DUPLICATE","Unique") -> Unique | P25: =IF(L25="","MISSING","OK") -> OK | Q25: =IF(ISNUMBER(B25),"OK","BAD DATE") -> OK | R25: =IF(ROUND(F25,2)=F25,"OK","FIX") -> OK
A26: ORD200024 | B26: 45595 | C26: C17470 | D26: Laptop | E26: 2 | F26: 230.95 | G26: 956 Main St | H26: Online | I26: Delivered | J26: TRK28775057 | K26: 3 | L26: WINTER15 | M26: Referral | N26: 461.9 | O26: =IF(COUNTIF($A$2:$A$1201,A26)>1,"DUPLICATE","Unique") -> Unique | P26: =IF(L26="","MISSING","OK") -> OK | Q26: =IF(ISNUMBER(B26),"OK","BAD DATE") -> OK | R26: =IF(ROUND(F26,2)=F26,"OK","FIX") -> OK
A27: ORD200025 | B27: 45497 | C27: C42577 | D27: Monitor | E27: 1 | F27: 399.98 | G27: 709 Main St | H27: Debit Card | I27: Delivered | J27: TRK69423327 | K27: 3 | L27: WINTER15 | M27: Email | N27: 399.98 | O27: =IF(COUNTIF($A$2:$A$1201,A27)>1,"DUPLICATE","Unique") -> Unique | P27: =IF(L27="","MISSING","OK") -> OK | Q27: =IF(ISNUMBER(B27),"OK","BAD DATE") -> OK | R27: =IF(ROUND(F27,2)=F27,"OK","FIX") -> OK
A28: ORD200026 | B28: 45357 | C28: C21944 | D28: Laptop | E28: 5 | F28: 59.55 | G28: 296 Main St | H28: Online | I28: Delivered | J28: TRK80276812 | K28: 6 | M28: Referral | N28: 297.75 | O28: =IF(COUNTIF($A$2:$A$1201,A28)>1,"DUPLICATE","Unique") -> Unique | P28: =IF(L28="","MISSING","OK") -> MISSING | Q28: =IF(ISNUMBER(B28),"OK","BAD DATE") -> OK | R28: =IF(ROUND(F28,2)=F28,"OK","FIX") -> OK
A29: ORD200027 | B29: 45344 | C29: C97593 | D29: Printer | E29: 1 | F29: 472.74 | G29: 881 Main St | H29: Online | I29: Shipped | J29: TRK89117573 | K29: 6 | L29: WINTER15 | M29: Google | N29: 472.74 | O29: =IF(COUNTIF($A$2:$A$1201,A29)>1,"DUPLICATE","Unique") -> Unique | P29: =IF(L29="","MISSING","OK") -> OK | Q29: =IF(ISNUMBER(B29),"OK","BAD DATE") -> OK | R29: =IF(ROUND(F29,2)=F29,"OK","FIX") -> OK
A30: ORD200028 | B30: 45251 | C30: C59823 | D30: Phone | E30: 4 | F30: 160.07 | G30: 568 Main St | H30: Online | I30: Pending | J30: TRK65895539 | K30: 5 | M30: Email | N30: 640.28 | O30: =IF(COUNTIF($A$2:$A$1201,A30)>1,"DUPLICATE","Unique") -> Unique | P30: =IF(L30="","MISSING","OK") -> MISSING | Q30: =IF(ISNUMBER(B30),"OK","BAD DATE") -> OK | R30: =IF(ROUND(F30,2)=F30,"OK","FIX") -> OK
A31: ORD200029 | B31: 45555 | C31: C33260 | D31: Desk | E31: 3 | F31: 423.53 | G31: 930 Main St | H31: Credit Card | I31: Delivered | J31: TRK59744090 | K31: 6 | L31: SAVE10 | M31: Referral | N31: 1270.59 | O31: =IF(COUNTIF($A$2:$A$1201,A31)>1,"DUPLICATE","Unique") -> Unique | P31: =IF(L31="","MISSING","OK") -> OK | Q31: =IF(ISNUMBER(B31),"OK","BAD DATE") -> OK | R31: =IF(ROUND(F31,2)=F31,"OK","FIX") -> OK
A32: ORD200030 | B32: 45738 | C32: C44267 | D32: Monitor | E32: 2 | F32: 426.7 | G32: 895 Main St | H32: Online | I32: Pending | J32: TRK54751444 | K32: 5 | L32: SAVE10 | M32: Referral | N32: 853.4 | O32: =IF(COUNTIF($A$2:$A$1201,A32)>1,"DUPLICATE","Unique") -> Unique | P32: =IF(L32="","MISSING","OK") -> OK | Q32: =IF(ISNUMBER(B32),"OK","BAD DATE") -> OK | R32: =IF(ROUND(F32,2)=F32,"OK","FIX") -> OK
A33: ORD200031 | B33: 45107 | C33: C26445 | D33: Chair | E33: 3 | F33: 500.08 | G33: 996 Main St | H33: Debit Card | I33: Returned | J33: TRK31229981 | K33: 6 | M33: Facebook | N33: 1500.24 | O33: =IF(COUNTIF($A$2:$A$1201,A33)>1,"DUPLICATE","Unique") -> Unique | P33: =IF(L33="","MISSING","OK") -> MISSING | Q33: =IF(ISNUMBER(B33),"OK","BAD DATE") -> OK | R33: =IF(ROUND(F33,2)=F33,"OK","FIX") -> OK
A34: ORD200032 | B34: 45047 | C34: C12388 | D34: Tablet | E34: 5 | F34: 536.72 | G34: 830 Main St | H34: Cash | I34: Delivered | J34: TRK99261395 | K34: 10 | M34: Email | N34: 2683.6 | O34: =IF(COUNTIF($A$2:$A$1201,A34)>1,"DUPLICATE","Unique") -> Unique | P34: =IF(L34="","MISSING","OK") -> MISSING | Q34: =IF(ISNUMBER(B34),"OK","BAD DATE") -> OK | R34: =IF(ROUND(F34,2)=F34,"OK","FIX") -> OK
A35: ORD200033 | B35: 45082 | C35: C52184 | D35: Chair | E35: 1 | F35: 162.77 | G35: 912 Main St | H35: Online | I35: Cancelled | J35: TRK73312471 | K35: 4 | L35: WINTER15 | M35: Facebook | N35: 162.77 | O35: =IF(COUNTIF($A$2:$A$1201,A35)>1,"DUPLICATE","Unique") -> Unique | P35: =IF(L35="","MISSING","OK") -> OK | Q35: =IF(ISNUMBER(B35),"OK","BAD DATE") -> OK | R35: =IF(ROUND(F35,2)=F35,"OK","FIX") -> OK
A36: ORD200034 | B36: 44933 | C36: C67195 | D36: Chair | E36: 4 | F36: 576.52 | G36: 926 Main St | H36: Credit Card | I36: Pending | J36: TRK55467915 | K36: 5 | L36: WINTER15 | M36: Facebook | N36: 2306.08 | O36: =IF(COUNTIF($A$2:$A$1201,A36)>1,"DUPLICATE","Unique") -> Unique | P36: =IF(L36="","MISSING","OK") -> OK | Q36: =IF(ISNUMBER(B36),"OK","BAD DATE") -> OK | R36: =IF(ROUND(F36,2)=F36,"OK","FIX") -> OK
A37: ORD200035 | B37: 45633 | C37: C50304 | D37: Monitor | E37: 2 | F37: 465.15 | G37: 128 Main St | H37: Online | I37: Shipped | J37: TRK46850888 | K37: 2 | L37: SAVE10 | M37: Facebook | N37: 930.3 | O37: =IF(COUNTIF($A$2:$A$1201,A37)>1,"DUPLICATE","Unique") -> Unique | P37: =IF(L37="","MISSING","OK") -> OK | Q37: =IF(ISNUMBER(B37),"OK","BAD DATE") -> OK | R37: =IF(ROUND(F37,2)=F37,"OK","FIX") -> OK
A38: ORD200036 | B38: 45785 | C38: C59337 | D38: Laptop | E38: 2 | F38: 534.43 | G38: 465 Main St | H38: Debit Card | I38: Pending | J38: TRK50961250 | K38: 5 | M38: Facebook | N38: 1068.86 | O38: =IF(COUNTIF($A$2:$A$1201,A38)>1,"DUPLICATE","Unique") -> Unique | P38: =IF(L38="","MISSING","OK") -> MISSING | Q38: =IF(ISNUMBER(B38),"OK","BAD DATE") -> OK | R38: =IF(ROUND(F38,2)=F38,"OK","FIX") -> OK
A39: ORD200037 | B39: 45579 | C39: C10054 | D39: Laptop | E39: 2 | F39: 76.74 | G39: 409 Main St | H39: Cash | I39: Returned | J39: TRK94005261 | K39: 7 | L39: SAVE10 | M39: Instagram | N39: 153.48 | O39: =IF(COUNTIF($A$2:$A$1201,A39)>1,"DUPLICATE","Unique") -> Unique | P39: =IF(L39="","MISSING","OK") -> OK | Q39: =IF(ISNUMBER(B39),"OK","BAD DATE") -> OK | R39: =IF(ROUND(F39,2)=F39,"OK","FIX") -> OK
A40: ORD200038 | B40: 45645 | C40: C15924 | D40: Laptop | E40: 1 | F40: 245.89 | G40: 549 Main St | H40: Debit Card | I40: Delivered | J40: TRK14835975 | K40: 3 | L40: SAVE10 | M40: Google | N40: 245.89 | O40: =IF(COUNTIF($A$2:$A$1201,A40)>1,"DUPLICATE","Unique") -> Unique | P40: =IF(L40="","MISSING","OK") -> OK | Q40: =IF(ISNUMBER(B40),"OK","BAD DATE") -> OK | R40: =IF(ROUND(F40,2)=F40,"OK","FIX") -> OK
...

Sheet Cleaned_Data
A1: OrderID | B1: Date | C1: CustomerID | D1: Product | E1: Quantity | F1: UnitPrice | G1: ShippingAddress | H1: PaymentMethod | I1: OrderStatus | J1: TrackingNumber | K1: ItemsInCart | L1: CouponCode | M1: ReferralSource | N1: TotalPrice | O1: Duplicate_Check | P1: Missing_Check | Q1: Date_Check | R1: Precision_Check
A2: =TRIM(UPPER(Raw_Data!A2)) -> ORD200000 | B2: =IF(ISNUMBER(Raw_Data!B2),Raw_Data!B2,DATEVALUE(Raw_Data!B2)) -> 44930 | C2: =TRIM(UPPER(Raw_Data!C2)) -> C72649 | D2: =PROPER(TRIM(Raw_Data!D2)) -> Monitor | E2: =Raw_Data!E2 -> 5 | F2: =ROUND(Raw_Data!F2,2) -> 570.62 | G2: =PROPER(TRIM(Raw_Data!G2)) -> 928 Main St | H2: =PROPER(TRIM(Raw_Data!H2)) -> Debit Card | I2: =PROPER(TRIM(Raw_Data!I2)) -> Shipped | J2: =TRIM(UPPER(Raw_Data!J2)) -> TRK37947903 | K2: =Raw_Data!K2 -> 7 | L2: =IF(TRIM(Raw_Data!L2)="","No Coupon",TRIM(UPPER(Raw_Data!L2))) -> SAVE10 | M2: =PROPER(TRIM(Raw_Data!M2)) -> Instagram | N2: =ROUND(E2*F2,2) -> 2853.1 | O2: =IF(COUNTIF($A$2:$A$1201,A2)>1,"DUPLICATE","Unique") -> Unique | P2: =IF(L2="","MISSING","OK") -> OK | Q2: =IF(ISNUMBER(B2),"OK","BAD DATE") -> OK | R2: =IF(ROUND(F2,2)=F2,"OK","FIX") -> OK
A3: =TRIM(UPPER(Raw_Data!A3)) -> ORD200001 | B3: =IF(ISNUMBER(Raw_Data!B3),Raw_Data!B3,DATEVALUE(Raw_Data!B3)) -> 45527 | C3: =TRIM(UPPER(Raw_Data!C3)) -> C75739 | D3: =PROPER(TRIM(Raw_Data!D3)) -> Phone | E3: =Raw_Data!E3 -> 2 | F3: =ROUND(Raw_Data!F3,2) -> 151.35 | G3: =PROPER(TRIM(Raw_Data!G3)) -> 823 Main St | H3: =PROPER(TRIM(Raw_Data!H3)) -> Online | I3: =PROPER(TRIM(Raw_Data!I3)) -> Shipped | J3: =TRIM(UPPER(Raw_Data!J3)) -> TRK91186779 | K3: =Raw_Data!K3 -> 3 | L3: =IF(TRIM(Raw_Data!L3)="","No Coupon",TRIM(UPPER(Raw_Data!L3))) -> SAVE10 | M3: =PROPER(TRIM(Raw_Data!M3)) -> Referral | N3: =ROUND(E3*F3,2) -> 302.7 | O3: =IF(COUNTIF($A$2:$A$1201,A3)>1,"DUPLICATE","Unique") -> Unique | P3: =IF(L3="","MISSING","OK") -> OK | Q3: =IF(ISNUMBER(B3),"OK","BAD DATE") -> OK | R3: =IF(ROUND(F3,2)=F3,"OK","FIX") -> OK
A4: =TRIM(UPPER(Raw_Data!A4)) -> ORD200002 | B4: =IF(ISNUMBER(Raw_Data!B4),Raw_Data!B4,DATEVALUE(Raw_Data!B4)) -> 45349 | C4: =TRIM(UPPER(Raw_Data!C4)) -> C81728 | D4: =PROPER(TRIM(Raw_Data!D4)) -> Tablet | E4: =Raw_Data!E4 -> 5 | F4: =ROUND(Raw_Data!F4,2) -> 550.68 | G4: =PROPER(TRIM(Raw_Data!G4)) -> 512 Main St | H4: =PROPER(TRIM(Raw_Data!H4)) -> Credit Card | I4: =PROPER(TRIM(Raw_Data!I4)) -> Cancelled | J4: =TRIM(UPPER(Raw_Data!J4)) -> TRK42903982 | K4: =Raw_Data!K4 -> 8 | L4: =IF(TRIM(Raw_Data!L4)="","No Coupon",TRIM(UPPER(Raw_Data!L4))) -> FREESHIP | M4: =PROPER(TRIM(Raw_Data!M4)) -> Email | N4: =ROUND(E4*F4,2) -> 2753.4 | O4: =IF(COUNTIF($A$2:$A$1201,A4)>1,"DUPLICATE","Unique") -> Unique | P4: =IF(L4="","MISSING","OK") -> OK | Q4: =IF(ISNUMBER(B4),"OK","BAD DATE") -> OK | R4: =IF(ROUND(F4,2)=F4,"OK","FIX") -> OK
A5: =TRIM(UPPER(Raw_Data!A5)) -> ORD200003 | B5: =IF(ISNUMBER(Raw_Data!B5),Raw_Data!B5,DATEVALUE(Raw_Data!B5)) -> 45214 | C5: =TRIM(UPPER(Raw_Data!C5)) -> C33540 | D5: =PROPER(TRIM(Raw_Data!D5)) -> Chair | E5: =Raw_Data!E5 -> 1 | F5: =ROUND(Raw_Data!F5,2) -> 273.19 | G5: =PROPER(TRIM(Raw_Data!G5)) -> 275 Main St | H5: =PROPER(TRIM(Raw_Data!H5)) -> Debit Card | I5: =PROPER(TRIM(Raw_Data!I5)) -> Returned | J5: =TRIM(UPPER(Raw_Data!J5)) -> TRK62788070 | K5: =Raw_Data!K5 -> 5 | L5: =IF(TRIM(Raw_Data!L5)="","No Coupon",TRIM(UPPER(Raw_Data!L5))) -> SAVE10 | M5: =PROPER(TRIM(Raw_Data!M5)) -> Facebook | N5: =ROUND(E5*F5,2) -> 273.19 | O5: =IF(COUNTIF($A$2:$A$1201,A5)>1,"DUPLICATE","Unique") -> Unique | P5: =IF(L5="","MISSING","OK") -> OK | Q5: =IF(ISNUMBER(B5),"OK","BAD DATE") -> OK | R5: =IF(ROUND(F5,2)=F5,"OK","FIX") -> OK
A6: =TRIM(UPPER(Raw_Data!A6)) -> ORD200004 | B6: =IF(ISNUMBER(Raw_Data!B6),Raw_Data!B6,DATEVALUE(Raw_Data!B6)) -> 45785 | C6: =TRIM(UPPER(Raw_Data!C6)) -> C81840 | D6: =PROPER(TRIM(Raw_Data!D6)) -> Printer | E6: =Raw_Data!E6 -> 4 | F6: =ROUND(Raw_Data!F6,2) -> 626.01 | G6: =PROPER(TRIM(Raw_Data!G6)) -> 668 Main St | H6: =PROPER(TRIM(Raw_Data!H6)) -> Online | I6: =PROPER(TRIM(Raw_Data!I6)) -> Delivered | J6: =TRIM(UPPER(Raw_Data!J6)) -> TRK29241424 | K6: =Raw_Data!K6 -> 8 | L6: =IF(TRIM(Raw_Data!L6)="","No Coupon",TRIM(UPPER(Raw_Data!L6))) -> SAVE10 | M6: =PROPER(TRIM(Raw_Data!M6)) -> Email | N6: =ROUND(E6*F6,2) -> 2504.04 | O6: =IF(COUNTIF($A$2:$A$1201,A6)>1,"DUPLICATE","Unique") -> Unique | P6: =IF(L6="","MISSING","OK") -> OK | Q6: =IF(ISNUMBER(B6),"OK","BAD DATE") -> OK | R6: =IF(ROUND(F6,2)=F6,"OK","FIX") -> OK
A7: =TRIM(UPPER(Raw_Data!A7)) -> ORD200005 | B7: =IF(ISNUMBER(Raw_Data!B7),Raw_Data!B7,DATEVALUE(Raw_Data!B7)) -> 45222 | C7: =TRIM(UPPER(Raw_Data!C7)) -> C37249 | D7: =PROPER(TRIM(Raw_Data!D7)) -> Phone | E7: =Raw_Data!E7 -> 2 | F7: =ROUND(Raw_Data!F7,2) -> 245.86 | G7: =PROPER(TRIM(Raw_Data!G7)) -> 934 Main St | H7: =PROPER(TRIM(Raw_Data!H7)) -> Credit Card | I7: =PROPER(TRIM(Raw_Data!I7)) -> Shipped | J7: =TRIM(UPPER(Raw_Data!J7)) -> TRK72976927 | K7: =Raw_Data!K7 -> 4 | L7: =IF(TRIM(Raw_Data!L7)="","No Coupon",TRIM(UPPER(Raw_Data!L7))) -> SAVE10 | M7: =PROPER(TRIM(Raw_Data!M7)) -> Instagram | N7: =ROUND(E7*F7,2) -> 491.72 | O7: =IF(COUNTIF($A$2:$A$1201,A7)>1,"DUPLICATE","Unique") -> Unique | P7: =IF(L7="","MISSING","OK") -> OK | Q7: =IF(ISNUMBER(B7),"OK","BAD DATE") -> OK | R7: =IF(ROUND(F7,2)=F7,"OK","FIX") -> OK
A8: =TRIM(UPPER(Raw_Data!A8)) -> ORD200006 | B8: =IF(ISNUMBER(Raw_Data!B8),Raw_Data!B8,DATEVALUE(Raw_Data!B8)) -> 45825 | C8: =TRIM(UPPER(Raw_Data!C8)) -> C83492 | D8: =PROPER(TRIM(Raw_Data!D8)) -> Laptop | E8: =Raw_Data!E8 -> 1 | F8: =ROUND(Raw_Data!F8,2) -> 664.42 | G8: =PROPER(TRIM(Raw_Data!G8)) -> 986 Main St | H8: =PROPER(TRIM(Raw_Data!H8)) -> Gift Card | I8: =PROPER(TRIM(Raw_Data!I8)) -> Returned | J8: =TRIM(UPPER(Raw_Data!J8)) -> TRK96417362 | K8: =Raw_Data!K8 -> 6 | L8: =IF(TRIM(Raw_Data!L8)="","No Coupon",TRIM(UPPER(Raw_Data!L8))) -> SAVE10 | M8: =PROPER(TRIM(Raw_Data!M8)) -> Facebook | N8: =ROUND(E8*F8,2) -> 664.42 | O8: =IF(COUNTIF($A$2:$A$1201,A8)>1,"DUPLICATE","Unique") -> Unique | P8: =IF(L8="","MISSING","OK") -> OK | Q8: =IF(ISNUMBER(B8),"OK","BAD DATE") -> OK | R8: =IF(ROUND(F8,2)=F8,"OK","FIX") -> OK
A9: =TRIM(UPPER(Raw_Data!A9)) -> ORD200007 | B9: =IF(ISNUMBER(Raw_Data!B9),Raw_Data!B9,DATEVALUE(Raw_Data!B9)) -> 45058 | C9: =TRIM(UPPER(Raw_Data!C9)) -> C41460 | D9: =PROPER(TRIM(Raw_Data!D9)) -> Monitor | E9: =Raw_Data!E9 -> 5 | F9: =ROUND(Raw_Data!F9,2) -> 149.55 | G9: =PROPER(TRIM(Raw_Data!G9)) -> 706 Main St | H9: =PROPER(TRIM(Raw_Data!H9)) -> Cash | I9: =PROPER(TRIM(Raw_Data!I9)) -> Shipped | J9: =TRIM(UPPER(Raw_Data!J9)) -> TRK78809193 | K9: =Raw_Data!K9 -> 9 | L9: =IF(TRIM(Raw_Data!L9)="","No Coupon",TRIM(UPPER(Raw_Data!L9))) -> FREESHIP | M9: =PROPER(TRIM(Raw_Data!M9)) -> Facebook | N9: =ROUND(E9*F9,2) -> 747.75 | O9: =IF(COUNTIF($A$2:$A$1201,A9)>1,"DUPLICATE","Unique") -> Unique | P9: =IF(L9="","MISSING","OK") -> OK | Q9: =IF(ISNUMBER(B9),"OK","BAD DATE") -> OK | R9: =IF(ROUND(F9,2)=F9,"OK","FIX") -> OK
A10: =TRIM(UPPER(Raw_Data!A10)) -> ORD200008 | B10: =IF(ISNUMBER(Raw_Data!B10),Raw_Data!B10,DATEVALUE(Raw_Data!B10)) -> 45749 | C10: =TRIM(UPPER(Raw_Data!C10)) -> C26817 | D10: =PROPER(TRIM(Raw_Data!D10)) -> Phone | E10: =Raw_Data!E10 -> 2 | F10: =ROUND(Raw_Data!F10,2) -> 134.28 | G10: =PROPER(TRIM(Raw_Data!G10)) -> 904 Main St | H10: =PROPER(TRIM(Raw_Data!H10)) -> Gift Card | I10: =PROPER(TRIM(Raw_Data!I10)) -> Cancelled | J10: =TRIM(UPPER(Raw_Data!J10)) -> TRK61042692 | K10: =Raw_Data!K10 -> 2 | L10: =IF(TRIM(Raw_Data!L10)="","No Coupon",TRIM(UPPER(Raw_Data!L10))) -> No Coupon | M10: =PROPER(TRIM(Raw_Data!M10)) -> Email | N10: =ROUND(E10*F10,2) -> 268.56 | O10: =IF(COUNTIF($A$2:$A$1201,A10)>1,"DUPLICATE","Unique") -> Unique | P10: =IF(L10="","MISSING","OK") -> OK | Q10: =IF(ISNUMBER(B10),"OK","BAD DATE") -> OK | R10: =IF(ROUND(F10,2)=F10,"OK","FIX") -> OK
A11: =TRIM(UPPER(Raw_Data!A11)) -> ORD200009 | B11: =IF(ISNUMBER(Raw_Data!B11),Raw_Data!B11,DATEVALUE(Raw_Data!B11)) -> 45251 | C11: =TRIM(UPPER(Raw_Data!C11)) -> C31946 | D11: =PROPER(TRIM(Raw_Data!D11)) -> Desk | E11: =Raw_Data!E11 -> 4 | F11: =ROUND(Raw_Data!F11,2) -> 509.38 | G11: =PROPER(TRIM(Raw_Data!G11)) -> 102 Main St | H11: =PROPER(TRIM(Raw_Data!H11)) -> Credit Card | I11: =PROPER(TRIM(Raw_Data!I11)) -> Shipped | J11: =TRIM(UPPER(Raw_Data!J11)) -> TRK33478363 | K11: =Raw_Data!K11 -> 6 | L11: =IF(TRIM(Raw_Data!L11)="","No Coupon",TRIM(UPPER(Raw_Data!L11))) -> SAVE10 | M11: =PROPER(TRIM(Raw_Data!M11)) -> Google | N11: =ROUND(E11*F11,2) -> 2037.52 | O11: =IF(COUNTIF($A$2:$A$1201,A11)>1,"DUPLICATE","Unique") -> Unique | P11: =IF(L11="","MISSING","OK") -> OK | Q11: =IF(ISNUMBER(B11),"OK","BAD DATE") -> OK | R11: =IF(ROUND(F11,2)=F11,"OK","FIX") -> OK
A12: =TRIM(UPPER(Raw_Data!A12)) -> ORD200010 | B12: =IF(ISNUMBER(Raw_Data!B12),Raw_Data!B12,DATEVALUE(Raw_Data!B12)) -> 45289 | C12: =TRIM(UPPER(Raw_Data!C12)) -> C43443 | D12: =PROPER(TRIM(Raw_Data!D12)) -> Tablet | E12: =Raw_Data!E12 -> 5 | F12: =ROUND(Raw_Data!F12,2) -> 625.97 | G12: =PROPER(TRIM(Raw_Data!G12)) -> 333 Main St | H12: =PROPER(TRIM(Raw_Data!H12)) -> Credit Card | I12: =PROPER(TRIM(Raw_Data!I12)) -> Returned | J12: =TRIM(UPPER(Raw_Data!J12)) -> TRK98859248 | K12: =Raw_Data!K12 -> 9 | L12: =IF(TRIM(Raw_Data!L12)="","No Coupon",TRIM(UPPER(Raw_Data!L12))) -> WINTER15 | M12: =PROPER(TRIM(Raw_Data!M12)) -> Instagram | N12: =ROUND(E12*F12,2) -> 3129.85 | O12: =IF(COUNTIF($A$2:$A$1201,A12)>1,"DUPLICATE","Unique") -> Unique | P12: =IF(L12="","MISSING","OK") -> OK | Q12: =IF(ISNUMBER(B12),"OK","BAD DATE") -> OK | R12: =IF(ROUND(F12,2)=F12,"OK","FIX") -> OK
A13: =TRIM(UPPER(Raw_Data!A13)) -> ORD200011 | B13: =IF(ISNUMBER(Raw_Data!B13),Raw_Data!B13,DATEVALUE(Raw_Data!B13)) -> 45339 | C13: =TRIM(UPPER(Raw_Data!C13)) -> C93861 | D13: =PROPER(TRIM(Raw_Data!D13)) -> Monitor | E13: =Raw_Data!E13 -> 3 | F13: =ROUND(Raw_Data!F13,2) -> 49.14 | G13: =PROPER(TRIM(Raw_Data!G13)) -> 831 Main St | H13: =PROPER(TRIM(Raw_Data!H13)) -> Online | I13: =PROPER(TRIM(Raw_Data!I13)) -> Returned | J13: =TRIM(UPPER(Raw_Data!J13)) -> TRK48234646 | K13: =Raw_Data!K13 -> 7 | L13: =IF(TRIM(Raw_Data!L13)="","No Coupon",TRIM(UPPER(Raw_Data!L13))) -> SAVE10 | M13: =PROPER(TRIM(Raw_Data!M13)) -> Email | N13: =ROUND(E13*F13,2) -> 147.42 | O13: =IF(COUNTIF($A$2:$A$1201,A13)>1,"DUPLICATE","Unique") -> Unique | P13: =IF(L13="","MISSING","OK") -> OK | Q13: =IF(ISNUMBER(B13),"OK","BAD DATE") -> OK | R13: =IF(ROUND(F13,2)=F13,"OK","FIX") -> OK
... A1201: =TRIM(UPPER(Raw_Data!A1201)) -> ORD201199 | B1201: =IF(ISNUMBER(Raw_Data!B1201),Raw_Data!B1201,DATEVALUE(Raw_Data!B1201)) -> 45088 | C1201: =TRIM(UPPER(Raw_Data!C1201)) -> C57502 | D1201: =PROPER(TRIM(Raw_Data!D1201)) -> Tablet | E1201: =Raw_Data!E1201 -> 4 | F1201: =ROUND(Raw_Data!F1201,2) -> 560.58 | G1201: =PROPER(TRIM(Raw_Data!G1201)) -> 201 Main St | H1201: =PROPER(TRIM(Raw_Data!H1201)) -> Gift Card | I1201: =PROPER(TRIM(Raw_Data!I1201)) -> Returned | J1201: =TRIM(UPPER(Raw_Data!J1201)) -> TRK51116746 | K1201: =Raw_Data!K1201 -> 6 | L1201: =IF(TRIM(Raw_Data!L1201)="","No Coupon",TRIM(UPPER(Raw_Data!L1201))) -> SAVE10 | M1201: =PROPER(TRIM(Raw_Data!M1201)) -> Referral | N1201: =ROUND(E1201*F1201,2) -> 2242.32 | O1201: =IF(COUNTIF($A$2:$A$1201,A1201)>1,"DUPLICATE","Unique") -> Unique | P1201: =IF(L1201="","MISSING","OK") -> OK | Q1201: =IF(ISNUMBER(B1201),"OK","BAD DATE") -> OK | R1201: =IF(ROUND(F1201,2)=F1201,"OK","FIX") -> OK
N1203: TOTAL ISSUES FOUND: | O1203: =COUNTIF(O2:O1201,"DUPLICATE")+COUNTIF(P2:P1201,"MISSING")+COUNTIF(Q2:Q1201,"BAD DATE")+COUNTIF(R2:R1201,"FIX") -> 0
N1204: STATUS: | O1204: =IF(O1203=0,"CLEAN","NEEDS REVIEW") -> CLEAN
